<robot
  name="mobile_d">
  <link
    name="base_link">
    <inertial>
      <origin
        xyz="-0.060188 0.067616 4.2907E-18"
        rpy="0 0 0" />
      <mass
        value="40.509" />
      <inertia
        ixx="0"
        ixy="0"
        ixz="0"
        iyy="0"
        iyz="0"
        izz="0" />
    </inertial>
    <visual>
      <origin
        xyz="0 0 0"
        rpy="0 0 0" />
      <geometry>
        <mesh
          filename="package://mobile_d/meshes/base_link.STL" />
      </geometry>
      <material
        name="">
        <color
          rgba="0.89804 0.91765 0.92941 1" />
      </material>
    </visual>
    <collision>
      <origin
        xyz="0 0 0"
        rpy="0 0 0" />
      <geometry>
        <mesh
          filename="package://mobile_d/meshes/base_link.STL" />
      </geometry>
    </collision>
  </link>
  <link
    name="wheel_connector">
    <inertial>
      <origin
        xyz="2.6171E-16 0.0017703 -0.00028056"
        rpy="0 0 0" />
      <mass
        value="0.34814" />
      <inertia
        ixx="0"
        ixy="0"
        ixz="0"
        iyy="0"
        iyz="0"
        izz="0" />
    </inertial>
    <visual>
      <origin
        xyz="0 0 0"
        rpy="0 0 0" />
      <geometry>
        <mesh
          filename="package://mobile_d/meshes/wheel_connector.STL" />
      </geometry>
      <material
        name="">
        <color
          rgba="0 0 0 1" />
      </material>
    </visual>
    <collision>
      <origin
        xyz="0 0 0"
        rpy="0 0 0" />
      <geometry>
        <mesh
          filename="package://mobile_d/meshes/wheel_connector.STL" />
      </geometry>
    </collision>
  </link>
  <joint
    name="base_to_connector"
    type="fixed">
    <origin
      xyz="0.076045 0 -0.013"
      rpy="1.5708 6.123E-17 1.5708" />
    <parent
      link="base_link" />
    <child
      link="wheel_connector" />
    <axis
      xyz="0 0 0" />
  </joint>
  <link
    name="left_wheel">
    <inertial>
      <origin
        xyz="-0.015139 1.2143E-17 5.8287E-16"
        rpy="0 0 0" />
      <mass
        value="0.28504" />
      <inertia
        ixx="0"
        ixy="0"
        ixz="0"
        iyy="0"
        iyz="0"
        izz="0" />
    </inertial>
    <visual>
      <origin
        xyz="0 0 0"
        rpy="0 0 0" />
      <geometry>
        <mesh
          filename="package://mobile_d/meshes/left_wheel.STL" />
      </geometry>
      <material
        name="">
        <color
          rgba="0.058824 0 0.83922 1" />
      </material>
    </visual>
    <collision>
      <origin
        xyz="0 0 0"
        rpy="0 0 0" />
      <geometry>
        <mesh
          filename="package://mobile_d/meshes/left_wheel.STL" />
      </geometry>
    </collision>
  </link>
  <joint
    name="base_to_lw"
    type="continuous">
    <origin
      xyz="0.076045 -0.148 -0.013"
      rpy="1.5708 6.123E-17 1.5708" />
    <parent
      link="base_link" />
    <child
      link="left_wheel" />
    <axis
      xyz="-1 0 0" />
    <dynamics
      friction="0.8" />
  </joint>
  <link
    name="right_wheel">
    <inertial>
      <origin
        xyz="0.015139 1.3878E-17 -5.8287E-16"
        rpy="0 0 0" />
      <mass
        value="0.28504" />
      <inertia
        ixx="0"
        ixy="0"
        ixz="0"
        iyy="0"
        iyz="0"
        izz="0" />
    </inertial>
    <visual>
      <origin
        xyz="0 0 0"
        rpy="0 0 0" />
      <geometry>
        <mesh
          filename="package://mobile_d/meshes/right_wheel.STL" />
      </geometry>
      <material
        name="">
        <color
          rgba="0.058824 0 0.83922 1" />
      </material>
    </visual>
    <collision>
      <origin
        xyz="0 0 0"
        rpy="0 0 0" />
      <geometry>
        <mesh
          filename="package://mobile_d/meshes/right_wheel.STL" />
      </geometry>
    </collision>
  </link>
  <joint
    name="base_to_rw"
    type="continuous">
    <origin
      xyz="0.076045 0.148 -0.013"
      rpy="1.5708 6.123E-17 1.5708" />
    <parent
      link="base_link" />
    <child
      link="right_wheel" />
    <axis
      xyz="-1 0 0" />
    <dynamics
      friction="0.8" />
  </joint>
  <link
    name="caster">
    <inertial>
      <origin
        xyz="0 0.023595 -2.4187E-16"
        rpy="0 0 0" />
      <mass
        value="0.52433" />
      <inertia
        ixx="0"
        ixy="0"
        ixz="0"
        iyy="0"
        iyz="0"
        izz="0" />
    </inertial>
    <visual>
      <origin
        xyz="0 0 0"
        rpy="0 0 0" />
      <geometry>
        <mesh
          filename="package://mobile_d/meshes/caster.STL" />
      </geometry>
      <material
        name="">
        <color
          rgba="0.79216 0.81961 0.93333 1" />
      </material>
    </visual>
    <collision>
      <origin
        xyz="0 0 0"
        rpy="0 0 0" />
      <geometry>
        <mesh
          filename="package://mobile_d/meshes/caster.STL" />
      </geometry>
    </collision>
  </link>
  <joint
    name="base_to_caster"
    type="fixed">
    <origin
      xyz="-0.185 0 0"
      rpy="-1.5708 0 0" />
    <parent
      link="base_link" />
    <child
      link="caster" />
    <axis
      xyz="0 -1 0" />
  </joint>
  <link
    name="lidar">
    <inertial>
      <origin
        xyz="0.16544 0.0375 0.15"
        rpy="0 0 0" />
      <mass
        value="0.43971" />
      <inertia
        ixx="0"
        ixy="0"
        ixz="0"
        iyy="0"
        iyz="0"
        izz="0" />
    </inertial>
    <visual>
      <origin
        xyz="0 0 0"
        rpy="0 0 0" />
      <geometry>
        <mesh
          filename="package://mobile_d/meshes/lidar.STL" />
      </geometry>
      <material
        name="">
        <color
          rgba="1 1 1 0.4" />
      </material>
    </visual>
    <collision>
      <origin
        xyz="0 0 0"
        rpy="0 0 0" />
      <geometry>
        <mesh
          filename="package://mobile_d/meshes/lidar.STL" />
      </geometry>
    </collision>
  </link>
  <joint
    name="base_to_lidar"
    type="fixed">
    <origin
      xyz="-0.025 0.15 0.05"
      rpy="1.5708 0 0" />
    <parent
      link="base_link" />
    <child
      link="lidar" />
    <axis
      xyz="0 1 0" />
  </joint>
  <link
    name="cam">
    <inertial>
      <origin
        xyz="0.0025 -2.7756E-17 -1.534E-19"
        rpy="0 0 0" />
      <mass
        value="0.0023856" />
      <inertia
        ixx="0"
        ixy="0"
        ixz="0"
        iyy="0"
        iyz="0"
        izz="0" />
    </inertial>
    <visual>
      <origin
        xyz="0 0 0"
        rpy="0 0 0" />
      <geometry>
        <mesh
          filename="package://mobile_d/meshes/cam.STL" />
      </geometry>
      <material
        name="">
        <color
          rgba="0 0 0 1" />
      </material>
    </visual>
    <collision>
      <origin
        xyz="0 0 0"
        rpy="0 0 0" />
      <geometry>
        <mesh
          filename="package://mobile_d/meshes/cam.STL" />
      </geometry>
    </collision>
  </link>
  <joint
    name="base_to_cam"
    type="fixed">
    <origin
      xyz="0.2225 0 0.135"
      rpy="1.5708 0 0" />
    <parent
      link="base_link" />
    <child
      link="cam" />
    <axis
      xyz="1 0 0" />
  </joint>

  <gazebo reference="caster">
 		<mu1>0.2</mu1>
 		<mu2>0.1</mu2>
 		<kp>1000000.0</kp>
 		<kd>100.0</kd>
 		<material>Gazebo/Orange</material>
 	</gazebo>

   <gazebo reference="base_link">
 		<kp>1000000.0</kp>
 		<kd>100.0</kd>
 		<material>Gazebo/Red</material>
 	</gazebo>


 	<gazebo reference="left_wheel">
 		<mu1>0.8</mu1>
 		<mu2>0.7</mu2>
 		<kp>500000.0</kp>
 		<kd>10000.0</kd>
 		<material>Gazebo/Black</material>
 	 	</gazebo>

 	<gazebo reference="right_wheel">
 		<mu1>0.8</mu1>
 		<mu2>0.7</mu2>
 		<kp>500000.0</kp>
 		<kd>10000.0</kd>
 		<material>Gazebo/Black</material>
 	</gazebo>

 	<gazebo reference="lidar">
 		<kp>500000.0</kp>
 		<kd>10000.0</kd>
 		<material>Gazebo/LightBlueLaser</material>
 	 	</gazebo>

  <gazebo>
 		<plugin name="mobile_d_controller" filename="libgazebo_ros_diff_drive.so">
 			<alwaysOn>true</alwaysOn>
 			<updateRate>20</updateRate>
 			<legacyMode>false</legacyMode>
 			<leftJoint>base_to_lw</leftJoint>
 			<rightJoint>base_to_rw</rightJoint>
 			<wheelSeparation>0.326</wheelSeparation>
 			<wheelDiameter>0.10076</wheelDiameter>
 			<wheelTorque>20</wheelTorque>
 			<wheelAcceleration>1</wheelAcceleration>
 			<commandTopic>cmd_vel</commandTopic>
 			<odometryTopic>odom</odometryTopic>
 			<odometryFrame>odom</odometryFrame>
 			<odometrySource>world</odometrySource>
 			<publishOdomTF>true</publishOdomTF>
 			<publishWheelJointState>true</publishWheelJointState>
 			<publishWheelTF>false</publishWheelTF>
 			<publishTf>true</publishTf>
 			<robotBaseFrame>base_link</robotBaseFrame>
 			<rosDebugLevel>na</rosDebugLevel>
 		</plugin>
 	</gazebo>

 	<gazebo reference="cam">
    <sensor type="camera" name="camera">
      <update_rate>30.0</update_rate>
      <camera name="head">
        <horizontal_fov>1.3962634</horizontal_fov>
        <image>
          <width>800</width>
          <height>400</height>
          <format>R8G8B8</format>
        </image>
        <clip>
          <near>0.04</near>
          <far>300</far>
        </clip>
        <noise>
          <type>gaussian</type>
          <!-- Noise is sampled indepdently per pixel on each frame.
               That pixel's noise value is added to each of its color
               channels, which at that point lie in the range [0,1]. -->
          <mean>0.0</mean>
          <stddev>0.007</stddev>
        </noise>
      </camera>
      <plugin name="camera_controller" filename="libgazebo_ros_camera.so">
        <alwaysOn>true</alwaysOn>
        <updateRate>0.0</updateRate>
        <cameraName>camera</cameraName>
        <imageTopicName>image_raw</imageTopicName>
        <cameraInfoTopicName>camera_info</cameraInfoTopicName>
        <frameName>cam</frameName>
        <hackBaseline>0.07</hackBaseline>
        <distortionK1>0.0</distortionK1>
        <distortionK2>0.0</distortionK2>
        <distortionK3>0.0</distortionK3>
        <distortionT1>0.0</distortionT1>
        <distortionT2>0.0</distortionT2>
      </plugin>
    </sensor>
  </gazebo>
</robot>