<robot
  name="mobile_d">
  <link
    name="base_link">
    <inertial>
      <origin
        xyz="-0.044346 -0.0049941 1.2129E-17"
        rpy="0 0 0" />
      <mass
        value="40.613" />
      <inertia
        ixx="0.38305"
        ixy="0.033175"
        ixz="9.0184E-19"
        iyy="1.0123"
        iyz="2.1978E-17"
        izz="0.80083" />
    </inertial>
    <visual>
      <origin
        xyz="0 0 0"
        rpy="0 0 0" />
      <geometry>
        <mesh
          filename="package://mobile_d/meshes/base_link.STL" />
      </geometry>
      <material
        name="">
        <color
          rgba="0.89804 0.91765 0.92941 1" />
      </material>
    </visual>
    <collision>
      <origin
        xyz="0 0 0"
        rpy="0 0 0" />
      <geometry>
        <mesh
          filename="package://mobile_d/meshes/base_link.STL" />
      </geometry>
    </collision>
  </link>
  <link
    name="wheel_connector">
    <inertial>
      <origin
        xyz="0 0.0025045 6.6467E-18"
        rpy="0 0 0" />
      <mass
        value="0.3799" />
      <inertia
        ixx="0.0021667"
        ixy="2.4474E-21"
        ixz="-5.8597E-21"
        iyy="0.002185"
        iyz="5.0845E-21"
        izz="4.7576E-05" />
    </inertial>
    <visual>
      <origin
        xyz="0 0 0"
        rpy="0 0 0" />
      <geometry>
        <mesh
          filename="package://mobile_d/meshes/wheel_connector.STL" />
      </geometry>
      <material
        name="">
        <color
          rgba="0.89804 0.91765 0.92941 1" />
      </material>
    </visual>
    <collision>
      <origin
        xyz="0 0 0"
        rpy="0 0 0" />
      <geometry>
        <mesh
          filename="package://mobile_d/meshes/wheel_connector.STL" />
      </geometry>
    </collision>
  </link>
  <joint
    name="base_to_connector"
    type="fixed">
    <origin
      xyz="0.075 0 -0.0875"
      rpy="1.5708 0 0" />
    <parent
      link="base_link" />
    <child
      link="wheel_connector" />
    <axis
      xyz="0 0 0" />
  </joint>
  <link
    name="left_wheel">
    <inertial>
      <origin
        xyz="0.015139 -1.3878E-17 0"
        rpy="0 0 0" />
      <mass
        value="0.28504" />
      <inertia
        ixx="0.00036186"
        ixy="5.3147E-23"
        ixz="-1.7654E-21"
        iyy="0.00020169"
        iyz="-4.2352E-22"
        izz="0.00020169" />
    </inertial>
    <visual>
      <origin
        xyz="0 0 0"
        rpy="0 0 0" />
      <geometry>
        <mesh
          filename="package://mobile_d/meshes/left_wheel.STL" />
      </geometry>
      <material
        name="">
        <color
          rgba="0.29804 0.29804 0.29804 1" />
      </material>
    </visual>
    <collision>
      <origin
        xyz="0 0 0"
        rpy="0 0 0" />
      <geometry>
        <mesh
          filename="package://mobile_d/meshes/left_wheel.STL" />
      </geometry>
    </collision>
  </link>
  <joint
    name="base_to_lw"
    type="continuous">
    <origin
      xyz="0.075 -0.143 -0.0875"
      rpy="-1.585 -6.123E-17 -1.5708" />
    <parent
      link="base_link" />
    <child
      link="left_wheel" />
    <axis
      xyz="-1 0 0" />
    <dynamics
      friction="0.8" />
  </joint>
  <link
    name="right_wheel">
    <inertial>
      <origin
        xyz="-0.015139 -1.3878E-17 0"
        rpy="0 0 0" />
      <mass
        value="0.28504" />
      <inertia
        ixx="0.00036186"
        ixy="7.4336E-24"
        ixz="2.7919E-21"
        iyy="0.00020169"
        iyz="8.4703E-22"
        izz="0.00020169" />
    </inertial>
    <visual>
      <origin
        xyz="0 0 0"
        rpy="0 0 0" />
      <geometry>
        <mesh
          filename="package://mobile_d/meshes/right_wheel.STL" />
      </geometry>
      <material
        name="">
        <color
          rgba="0.29804 0.29804 0.29804 1" />
      </material>
    </visual>
    <collision>
      <origin
        xyz="0 0 0"
        rpy="0 0 0" />
      <geometry>
        <mesh
          filename="package://mobile_d/meshes/right_wheel.STL" />
      </geometry>
    </collision>
  </link>
  <joint
    name="base_to_rw"
    type="continuous">
    <origin
      xyz="0.075 0.143 -0.0875"
      rpy="-1.5828 -6.123E-17 -1.5708" />
    <parent
      link="base_link" />
    <child
      link="right_wheel" />
    <axis
      xyz="-1 0 0" />
    <dynamics
      friction="0.8" />
  </joint>
  <link
    name="cam">
    <inertial>
      <origin
        xyz="5.189E-16 -6.9389E-18 0.0025"
        rpy="0 0 0" />
      <mass
        value="0.0023856" />
      <inertia
        ixx="3.8518E-08"
        ixy="2.5625E-40"
        ixz="9.9702E-23"
        iyy="3.8518E-08"
        iyz="-8.6441E-41"
        izz="6.7096E-08" />
    </inertial>
    <visual>
      <origin
        xyz="0 0 0"
        rpy="0 0 0" />
      <geometry>
        <mesh
          filename="package://mobile_d/meshes/cam.STL" />
      </geometry>
      <material
        name="">
        <color
          rgba="0.89804 0.91765 0.92941 1" />
      </material>
    </visual>
    <collision>
      <origin
        xyz="0 0 0"
        rpy="0 0 0" />
      <geometry>
        <mesh
          filename="package://mobile_d/meshes/cam.STL" />
      </geometry>
    </collision>
  </link>
  <joint
    name="base_to_cam"
    type="fixed">
    <origin
      xyz="0.2375 0 0.0625"
      rpy="1.5708 6.123E-17 1.5708" />
    <parent
      link="base_link" />
    <child
      link="cam" />
    <axis
      xyz="0 1 0" />
  </joint>
  <link
    name="caster">
    <inertial>
      <origin
        xyz="0 0.024091 2.7061E-16"
        rpy="0 0 0" />
      <mass
        value="1.1631" />
      <inertia
        ixx="0.0010496"
        ixy="1.3496E-20"
        ixz="1.1114E-34"
        iyy="0.0016172"
        iyz="1.1306E-19"
        izz="0.0010496" />
    </inertial>
    <visual>
      <origin
        xyz="0 0 0"
        rpy="0 0 0" />
      <geometry>
        <mesh
          filename="package://mobile_d/meshes/caster.STL" />
      </geometry>
      <material
        name="">
        <color
          rgba="0.89804 0.91765 0.92941 1" />
      </material>
    </visual>
    <collision>
      <origin
        xyz="0 0 0"
        rpy="0 0 0" />
      <geometry>
        <mesh
          filename="package://mobile_d/meshes/caster.STL" />
      </geometry>
    </collision>
  </link>
  <joint
    name="base_to_caster"
    type="fixed">
    <origin
      xyz="-0.17 0 -0.0705"
      rpy="-1.5708 0 0" />
    <parent
      link="base_link" />
    <child
      link="caster" />
    <axis
      xyz="0 -1 0" />
  </joint>
  <link
    name="lidar">
    <inertial>
      <origin
        xyz="0.068952 0.0375 1.3883E-16"
        rpy="0 0 0" />
      <mass
        value="0.49665" />
      <inertia
        ixx="0.0078332"
        ixy="-7.2721E-19"
        ixz="1.2852E-18"
        iyy="0.010872"
        iyz="-1.7538E-20"
        izz="0.0035048" />
    </inertial>
    <visual>
      <origin
        xyz="0 0 0"
        rpy="0 0 0" />
      <geometry>
        <mesh
          filename="package://mobile_d/meshes/lidar.STL" />
      </geometry>
      <material
        name="">
        <color
          rgba="0.89804 0.91765 0.92941 1" />
      </material>
    </visual>
    <collision>
      <origin
        xyz="0 0 0"
        rpy="0 0 0" />
      <geometry>
        <mesh
          filename="package://mobile_d/meshes/lidar.STL" />
      </geometry>
    </collision>
  </link>
  <joint
    name="base_to_lidar"
    type="fixed">
    <origin
      xyz="0.0808 0 -0.0225"
      rpy="1.5708 0 0" />
    <parent
      link="base_link" />
    <child
      link="lidar" />
    <axis
      xyz="0 0 0" />
  </joint>

  <link name="vir_cam"/>

  <joint
    name="vir_to_cam"
    type="fixed">
    <origin
      xyz="0 0 0"
      rpy="0 -0.7805 -1.5708" />
    <parent
      link="cam" />
    <child
      link="vir_cam" />
    <axis
      xyz="0 1 0" />
  </joint>

  <link name="vir_lidar"/>

  <joint
    name="vir_lidar_to_lidar"
    type="fixed">
    <origin
      xyz="0.10 0.04 0"
      rpy="1.5708 0 0" />
    <parent
      link="lidar" />
    <child
      link="vir_lidar" />
    <axis
      xyz="0 0 0"
      rpy="0 0 0" />
  </joint>

  <gazebo reference="caster">
 		<mu1>0.2</mu1>
 		<mu2>0.1</mu2>
 		<kp>1000000.0</kp>
 		<kd>100.0</kd>
 		<material>Gazebo/Orange</material>
 	</gazebo>

   <gazebo reference="base_link">
 		<kp>1000000.0</kp>
 		<kd>100.0</kd>
 		<material>Gazebo/Red</material>
 	</gazebo>


 	<gazebo reference="left_wheel">
 		<mu1>0.8</mu1>
 		<mu2>0.7</mu2>
 		<kp>500000.0</kp>
 		<kd>10000.0</kd>
 		<material>Gazebo/Black</material>
 	 	</gazebo>

 	<gazebo reference="right_wheel">
 		<mu1>0.8</mu1>
 		<mu2>0.7</mu2>
 		<kp>500000.0</kp>
 		<kd>10000.0</kd>
 		<material>Gazebo/Black</material>
 	</gazebo>

 	<gazebo reference="lidar">
 		<kp>500000.0</kp>
 		<kd>10000.0</kd>
 		<material>Gazebo/LightBlueLaser</material>
 	 	</gazebo>

  <gazebo>
 		<plugin name="mobile_d_controller" filename="libgazebo_ros_diff_drive.so">
 			<alwaysOn>true</alwaysOn>
 			<updateRate>20</updateRate>
 			<legacyMode>false</legacyMode>
 			<leftJoint>base_to_lw</leftJoint>
 			<rightJoint>base_to_rw</rightJoint>
 			<wheelSeparation>0.326</wheelSeparation>
 			<wheelDiameter>0.10076</wheelDiameter>
 			<wheelTorque>20</wheelTorque>
 			<wheelAcceleration>1</wheelAcceleration>
 			<commandTopic>cmd_vel</commandTopic>
 			<odometryTopic>odom</odometryTopic>
 			<odometryFrame>odom</odometryFrame>
 			<odometrySource>world</odometrySource>
 			<publishOdomTF>true</publishOdomTF>
 			<publishWheelJointState>true</publishWheelJointState>
 			<publishWheelTF>false</publishWheelTF>
 			<publishTf>true</publishTf>
 			<robotBaseFrame>base_link</robotBaseFrame>
 			<rosDebugLevel>na</rosDebugLevel>
 		</plugin>
 	</gazebo>

 	<gazebo reference="vir_cam">
    <sensor type="camera" name="camera">
      <update_rate>30.0</update_rate>
      <camera name="head">
        <horizontal_fov>1.3962634</horizontal_fov>
        <image>
          <width>800</width>
          <height>400</height>
          <format>R8G8B8</format>
        </image>
        <clip>
          <near>0.04</near>
          <far>300</far>
        </clip>
        <noise>
          <type>gaussian</type>
          <!-- Noise is sampled indepdently per pixel on each frame.
               That pixel's noise value is added to each of its color
               channels, which at that point lie in the range [0,1]. -->
          <mean>0.0</mean>
          <stddev>0.007</stddev>
        </noise>
      </camera>
      <plugin name="camera_controller" filename="libgazebo_ros_camera.so">
        <alwaysOn>true</alwaysOn>
        <updateRate>0.0</updateRate>
        <cameraName>camera</cameraName>
        <imageTopicName>image_raw</imageTopicName>
        <cameraInfoTopicName>camera_info</cameraInfoTopicName>
        <frameName>vir_cam</frameName>
        <hackBaseline>0.07</hackBaseline>
        <distortionK1>0.0</distortionK1>
        <distortionK2>0.0</distortionK2>
        <distortionK3>0.0</distortionK3>
        <distortionT1>0.0</distortionT1>
        <distortionT2>0.0</distortionT2>
      </plugin>
    </sensor>
  </gazebo>

  <gazebo reference="vir_lidar">
    <sensor type="ray" name="lds_lfcd_sensor">
      <pose>0 0 0 0 0 0</pose>
      <visualize>false</visualize>
      <ray>
        <scan>
          <horizontal>
            <samples>360</samples>
            <resolution>1</resolution>
            <min_angle>-1.5708</min_angle>
            <max_angle>1.5708</max_angle>
          </horizontal>
        </scan>
        <range>
          <min>0.160</min>
          <max>3.5</max>
          <resolution>0.015</resolution>
        </range>
        <noise>
          <type>gaussian</type>
          <mean>0.0</mean>
          <stddev>0.01</stddev>
        </noise>
      </ray>
      <plugin name="gazebo_ros_lds_lfcd_controller" filename="libgazebo_ros_laser.so">
        <topicName>scan</topicName>
        <frameName>vir_lidar</frameName>
        <update_rate>1800</update_rate>
      </plugin>
    </sensor>
  </gazebo>
</robot>
